<?xml version="1.0" ?>
<!-- =================================================================================== -->
<!-- |    This document was autogenerated by xacro from src/patrol_robot_description/urdf/pabot/pabot.urdf.xacro | -->
<!-- |    EDITING THIS FILE BY HAND IS NOT RECOMMENDED                                 | -->
<!-- =================================================================================== -->
<robot name="pabot">
  <!-- 主文件，用来加载各个部分 / main file, to include all different components -->
  <gazebo reference="camera_link">
    <sensor name="camera_sensor" type="depth">
      <plugin filename="libgazebo_ros_camera.so" name="depth_camera">
        <frame_name>camera_optical_link</frame_name>
        <!--修正的改变朝向的camera,发布坐标系的frame_id-->
      </plugin>
      <always_on>true</always_on>
      <update_rate>10</update_rate>
      <camera name="camera">
        <horizontal_fov>1.5009831567</horizontal_fov>
        <image>
          <width>800</width>
          <height>600</height>
          <format>R8G8B8</format>
        </image>
        <distortion>
          <k1>0.0</k1>
          <k2>0.0</k2>
          <k3>0.0</k3>
          <p1>0.0</p1>
          <p2>0.0</p2>
          <center>0.5 0.5</center>
        </distortion>
      </camera>
    </sensor>
  </gazebo>
  <link name="base_footprint"/>
  <link name="base_link">
    <!-- 部件的外观描述 -->
    <visual>
      <!-- 沿着自己几何中心的偏移和旋转量 -->
      <origin rpy="0.0 0.0 0.0" xyz="0.0 0.0 0.0"/>
      <!-- 几何形状 -->
      <geometry>
        <!-- 圆柱体 [m] -->
        <cylinder length="0.12" radius="0.1"/>
      </geometry>
      <!-- 材质颜色 -->
      <material name="white">
        <color rgba="1.0 1.0 1.0 0.5"/>
      </material>
    </visual>
    <collision>
      <origin rpy="0.0 0.0 0.0" xyz="0.0 0.0 0.0"/>
      <geometry>
        <cylinder length="0.12" radius="0.1"/>
      </geometry>
      <material name="white">
        <color rgba="1.0 1.0 1.0 0.5"/>
      </material>
    </collision>
    <inertial>
      <mass value="1.0"/>
      <inertia ixx="0.0037000000000000006" ixy="0" ixz="0" iyy="0.0037000000000000006" iyz="0" izz="0.005000000000000001"/>
    </inertial>
  </link>
  <joint name="base_footprint_joint" type="fixed">
    <origin rpy="0.0 0.0 0.0" xyz="0.0 0.0 0.091"/>
    <parent link="base_footprint"/>
    <child link="base_link"/>
  </joint>
  <link name="camera_link">
    <visual>
      <origin rpy="0.0 0.0 0.0" xyz="0.0 0.0 0.0"/>
      <geometry>
        <box size="0.02 0.10 0.02"/>
      </geometry>
      <material name="black">
        <color rgba="0.0 0.0 0.0 0.5"/>
      </material>
    </visual>
    <collision>
      <origin rpy="0.0 0.0 0.0" xyz="0.0 0.0 0.0"/>
      <geometry>
        <box size="0.02 0.10 0.02"/>
      </geometry>
      <material name="black">
        <color rgba="0.0 0.0 0.0 0.5"/>
      </material>
    </collision>
    <inertial>
      <mass value="0.01"/>
      <inertia ixx="8.666666666666668e-06" ixy="0.0" ixz="0.0" iyy="6.666666666666667e-07" iyz="0.0" izz="8.666666666666668e-06"/>
    </inertial>
  </link>
  <!--虚拟部件,用于修正深度相机默认看z轴的问题-->
  <link name="camera_optical_link"/>
  <joint name="camera_joint" type="fixed">
    <origin rpy="0.0 0.0 0.0" xyz="0.10 0.0 0.075"/>
    <parent link="base_link"/>
    <child link="camera_link"/>
  </joint>
  <!--虚拟关节,配合使用-->
  <joint name="camera_optical_joint" type="fixed">
    <origin rpy="-1.5707963267948966 0.0 -1.5707963267948966" xyz="0 0 0"/>
    <parent link="camera_link"/>
    <child link="camera_optical_link"/>
  </joint>
  <gazebo reference="camera_link">
    <material>Gazebo/Grey</material>
  </gazebo>
  <!-- 机器人IMU部件，惯性测量传感器 -->
  <link name="imu_link">
    <visual>
      <origin rpy="0.0 0.0 0.0" xyz="0.0 0.0 0.0"/>
      <geometry>
        <box size="0.02 0.02 0.02"/>
      </geometry>
      <material name="black">
        <color rgba="0.0 0.0 0.0 0.5"/>
      </material>
    </visual>
    <collision>
      <origin rpy="0.0 0.0 0.0" xyz="0.0 0.0 0.0"/>
      <geometry>
        <box size="0.02 0.02 0.02"/>
      </geometry>
      <material name="black">
        <color rgba="0.0 0.0 0.0 0.5"/>
      </material>
    </collision>
    <inertial>
      <mass value="0.01"/>
      <inertia ixx="6.666666666666667e-07" ixy="0.0" ixz="0.0" iyy="6.666666666666667e-07" iyz="0.0" izz="6.666666666666667e-07"/>
    </inertial>
  </link>
  <!-- 机器人的关节，用于组合机器人的部件 -->
  <joint name="imu_joint" type="fixed">
    <origin rpy="0.0 0.0 0.0" xyz="0.0 0.0 0.02"/>
    <parent link="base_link"/>
    <child link="imu_link"/>
  </joint>
  <!-- 雷达支撑杆 -->
  <link name="laser_cylinder_link">
    <visual>
      <origin rpy="0.0 0.0 0.0" xyz="0.0 0.0 0.0"/>
      <geometry>
        <cylinder length="0.10" radius="0.01"/>
      </geometry>
      <material name="black">
        <color rgba="0.0 0.0 0.0 1.0"/>
      </material>
    </visual>
    <collision>
      <origin rpy="0.0 0.0 0.0" xyz="0.0 0.0 0.0"/>
      <geometry>
        <cylinder length="0.10" radius="0.01"/>
      </geometry>
      <material name="black">
        <color rgba="0.0 0.0 0.0 1.0"/>
      </material>
    </collision>
    <inertial>
      <mass value="0.01"/>
      <inertia ixx="8.583333333333335e-06" ixy="0" ixz="0" iyy="8.583333333333335e-06" iyz="0" izz="5.000000000000001e-07"/>
    </inertial>
  </link>
  <!-- 雷达 -->
  <link name="laser_link">
    <visual>
      <origin rpy="0.0 0.0 0.0" xyz="0.0 0.0 0.0"/>
      <geometry>
        <cylinder length="0.02" radius="0.02"/>
      </geometry>
      <material name="black">
        <color rgba="0.0 0.0 0.0 1.0"/>
      </material>
    </visual>
    <collision>
      <origin rpy="0.0 0.0 0.0" xyz="0.0 0.0 0.0"/>
      <geometry>
        <cylinder length="0.02" radius="0.02"/>
      </geometry>
      <material name="black">
        <color rgba="0.0 0.0 0.0 1.0"/>
      </material>
    </collision>
    <inertial>
      <mass value="0.03"/>
      <inertia ixx="4e-06" ixy="0" ixz="0" iyy="4e-06" iyz="0" izz="6e-06"/>
    </inertial>
  </link>
  <joint name="laser_cylinder_joint" type="fixed">
    <origin rpy="0.0 0.0 0.0" xyz="0.0 0.0 0.10"/>
    <parent link="base_link"/>
    <child link="laser_cylinder_link"/>
  </joint>
  <joint name="laser_joint" type="fixed">
    <origin rpy="0.0 0.0 0.0" xyz="0.0 0.0 0.05"/>
    <parent link="laser_cylinder_link"/>
    <child link="laser_link"/>
  </joint>
  <gazebo reference="laser_cylinder_link">
    <material>Gazebo/Black</material>
  </gazebo>
  <gazebo reference="laser_link">
    <material>Gazebo/Black</material>
  </gazebo>
  <!-- 这里需要分辨前后两个casters，所以给不同的名字 -->
  <link name="front_caster_link">
    <visual>
      <origin rpy="0 0.0 0.0" xyz="0.0 0.0 0.0"/>
      <geometry>
        <sphere radius="0.016"/>
      </geometry>
      <material name="yellow">
        <color rgba="1.0 1.0 0.0 0.8"/>
      </material>
    </visual>
    <collision>
      <origin rpy="0 0.0 0.0" xyz="0.0 0.0 0.0"/>
      <geometry>
        <sphere radius="0.016"/>
      </geometry>
      <material name="yellow">
        <color rgba="1.0 1.0 0.0 0.8"/>
      </material>
    </collision>
    <inertial>
      <mass value="0.01"/>
      <inertia ixx="1.024e-06" ixy="0.0" ixz="0.0" iyy="1.024e-06" iyz="0.0" izz="1.024e-06"/>
    </inertial>
  </link>
  <joint name="front_caster_joint" type="fixed">
    <origin rpy="0.0 0.0 0.0" xyz="0.08 0.0 -0.076"/>
    <parent link="base_link"/>
    <child link="front_caster_link"/>
  </joint>
  <gazebo reference="front_caster_link">
    <mu1 value="0.0"/>
    <!--切向摩擦系数-->
    <mu2 value="0.0"/>
    <!--法向摩擦系数-->
    <kp value="1000000000.0"/>
    <!--接触刚度系数 值越大表示越硬，避免物体“陷入”地面-->
    <kd value="1.0"/>
    <!--接触阻尼，值太小可能导致弹跳，值太大则容易造成迟滞-->
  </gazebo>
  <!-- 这里需要分辨前后两个casters，所以给不同的名字 -->
  <link name="back_caster_link">
    <visual>
      <origin rpy="0 0.0 0.0" xyz="0.0 0.0 0.0"/>
      <geometry>
        <sphere radius="0.016"/>
      </geometry>
      <material name="yellow">
        <color rgba="1.0 1.0 0.0 0.8"/>
      </material>
    </visual>
    <collision>
      <origin rpy="0 0.0 0.0" xyz="0.0 0.0 0.0"/>
      <geometry>
        <sphere radius="0.016"/>
      </geometry>
      <material name="yellow">
        <color rgba="1.0 1.0 0.0 0.8"/>
      </material>
    </collision>
    <inertial>
      <mass value="0.01"/>
      <inertia ixx="1.024e-06" ixy="0.0" ixz="0.0" iyy="1.024e-06" iyz="0.0" izz="1.024e-06"/>
    </inertial>
  </link>
  <joint name="back_caster_joint" type="fixed">
    <origin rpy="0.0 0.0 0.0" xyz="-0.08 0.0 -0.076"/>
    <parent link="base_link"/>
    <child link="back_caster_link"/>
  </joint>
  <gazebo reference="back_caster_link">
    <mu1 value="0.0"/>
    <!--切向摩擦系数-->
    <mu2 value="0.0"/>
    <!--法向摩擦系数-->
    <kp value="1000000000.0"/>
    <!--接触刚度系数 值越大表示越硬，避免物体“陷入”地面-->
    <kd value="1.0"/>
    <!--接触阻尼，值太小可能导致弹跳，值太大则容易造成迟滞-->
  </gazebo>
  <link name="left_wheel_link">
    <visual>
      <origin rpy="1.57079 0.0 0.0" xyz="0.0 0.0 0.0"/>
      <geometry>
        <cylinder length="0.04" radius="0.032"/>
      </geometry>
      <material name="yellow">
        <color rgba="1.0 1.0 0.0 0.8"/>
      </material>
    </visual>
    <collision>
      <origin rpy="1.57079 0.0 0.0" xyz="0.0 0.0 0.0"/>
      <geometry>
        <cylinder length="0.04" radius="0.032"/>
      </geometry>
      <material name="yellow">
        <color rgba="1.0 1.0 0.0 0.8"/>
      </material>
    </collision>
    <inertial>
      <mass value="0.1"/>
      <inertia ixx="3.8933333333333336e-05" ixy="0" ixz="0" iyy="3.8933333333333336e-05" iyz="0" izz="5.12e-05"/>
    </inertial>
  </link>
  <joint name="left_wheel_joint" type="continuous">
    <!-- continuous:无限旋转的轮子 -->
    <origin rpy="0.0 0.0 0.0" xyz="0 0.10 -0.06"/>
    <parent link="base_link"/>
    <child link="left_wheel_link"/>
    <axis xyz="0 1 0"/>
  </joint>
  <gazebo reference="left_wheel_link">
    <mu1 value="20.0"/>
    <mu2 value="20.0"/>
    <kp value="1000000000.0"/>
    <kd value="1.0"/>
  </gazebo>
  <link name="right_wheel_link">
    <visual>
      <origin rpy="1.57079 0.0 0.0" xyz="0.0 0.0 0.0"/>
      <geometry>
        <cylinder length="0.04" radius="0.032"/>
      </geometry>
      <material name="yellow">
        <color rgba="1.0 1.0 0.0 0.8"/>
      </material>
    </visual>
    <collision>
      <origin rpy="1.57079 0.0 0.0" xyz="0.0 0.0 0.0"/>
      <geometry>
        <cylinder length="0.04" radius="0.032"/>
      </geometry>
      <material name="yellow">
        <color rgba="1.0 1.0 0.0 0.8"/>
      </material>
    </collision>
    <inertial>
      <mass value="0.1"/>
      <inertia ixx="3.8933333333333336e-05" ixy="0" ixz="0" iyy="3.8933333333333336e-05" iyz="0" izz="5.12e-05"/>
    </inertial>
  </link>
  <joint name="right_wheel_joint" type="continuous">
    <!-- continuous:无限旋转的轮子 -->
    <origin rpy="0.0 0.0 0.0" xyz="0 -0.10 -0.06"/>
    <parent link="base_link"/>
    <child link="right_wheel_link"/>
    <axis xyz="0 1 0"/>
  </joint>
  <gazebo reference="right_wheel_link">
    <mu1 value="20.0"/>
    <mu2 value="20.0"/>
    <kp value="1000000000.0"/>
    <kd value="1.0"/>
  </gazebo>
  <gazebo reference="laser_link">
    <sensor name="laserscan" type="ray">
      <plugin filename="libgazebo_ros_ray_sensor.so" name="laserscan">
        <ros>
          <namespace>/</namespace>
          <remapping>~/out:=scan</remapping>
        </ros>
        <output_type>sensor_msgs/LaserScan</output_type>
        <frame_name>laser_link</frame_name>
        <!--LaserScan消息中的frame_id-->
      </plugin>
      <always_on>true</always_on>
      <visualize>true</visualize>
      <update_rate>10</update_rate>
      <pose>0 0 0 0 0 0</pose>
      <!-- 激光传感器配置 -->
      <ray>
        <!-- 设置扫描范围 -->
        <scan>
          <horizontal>
            <samples>360</samples>
            <resolution>1.000000</resolution>
            <min_angle>0.000000</min_angle>
            <max_angle>6.280000</max_angle>
          </horizontal>
        </scan>
        <!-- 设置扫描距离 -->
        <range>
          <min>0.120000</min>
          <max>8.0</max>
          <resolution>0.015000</resolution>
        </range>
        <!-- 设置噪声 -->
        <noise>
          <type>gaussian</type>
          <mean>0.0</mean>
          <stddev>0.01</stddev>
        </noise>
      </ray>
    </sensor>
  </gazebo>
  <gazebo reference="imu_link">
    <sensor name="imu_sensor" type="imu">
      <plugin filename="libgazebo_ros_imu_sensor.so" name="imu_plugin">
        <ros>
          <namespace>/</namespace>
          <remapping>~/out:=imu</remapping>
        </ros>
        <initial_orientation_as_reference>false</initial_orientation_as_reference>
      </plugin>
      <update_rate>100</update_rate>
      <always_on>true</always_on>
      <!-- 六轴噪声设置 -->
      <imu>
        <angular_velocity>
          <x>
            <noise type="gaussian">
              <mean>0.0</mean>
              <stddev>2e-4</stddev>
              <bias_mean>0.0000075</bias_mean>
              <bias_stddev>0.0000008</bias_stddev>
            </noise>
          </x>
          <y>
            <noise type="gaussian">
              <mean>0.0</mean>
              <stddev>2e-4</stddev>
              <bias_mean>0.0000075</bias_mean>
              <bias_stddev>0.0000008</bias_stddev>
            </noise>
          </y>
          <z>
            <noise type="gaussian">
              <mean>0.0</mean>
              <stddev>2e-4</stddev>
              <bias_mean>0.0000075</bias_mean>
              <bias_stddev>0.0000008</bias_stddev>
            </noise>
          </z>
        </angular_velocity>
        <linear_acceleration>
          <x>
            <noise type="gaussian">
              <mean>0.0</mean>
              <stddev>1.7e-2</stddev>
              <bias_mean>0.1</bias_mean>
              <bias_stddev>0.001</bias_stddev>
            </noise>
          </x>
          <y>
            <noise type="gaussian">
              <mean>0.0</mean>
              <stddev>1.7e-2</stddev>
              <bias_mean>0.1</bias_mean>
              <bias_stddev>0.001</bias_stddev>
            </noise>
          </y>
          <z>
            <noise type="gaussian">
              <mean>0.0</mean>
              <stddev>1.7e-2</stddev>
              <bias_mean>0.1</bias_mean>
              <bias_stddev>0.001</bias_stddev>
            </noise>
          </z>
        </linear_acceleration>
      </imu>
    </sensor>
  </gazebo>
  <ros2_control name="PabotGazeboSystem" type="system">
    <!--ros2_control 控制接口定义-->
    <hardware>
      <!--使用官方插件 gazebo_ros2_control 来与 Gazebo 模拟物理系统通信-->
      <plugin>gazebo_ros2_control/GazeboSystem</plugin>
    </hardware>
    <joint name="left_wheel_joint">
      <command_interface name="velocity">
        <param name="min">-1</param>
        <param name="max">1</param>
      </command_interface>
      <command_interface name="effort">
        <param name="min">-0.1</param>
        <param name="max">0.1</param>
      </command_interface>
      <state_interface name="position"/>
      <!--读取当前角度或位置-->
      <state_interface name="velocity"/>
      <!--读取当前转速-->
      <state_interface name="effort"/>
      <!--读取当前受力或力矩-->
    </joint>
    <joint name="right_wheel_joint">
      <command_interface name="velocity">
        <param name="min">-1</param>
        <param name="max">1</param>
      </command_interface>
      <command_interface name="effort">
        <param name="min">-0.1</param>
        <param name="max">0.1</param>
      </command_interface>
      <state_interface name="position"/>
      <state_interface name="velocity"/>
      <state_interface name="effort"/>
    </joint>
  </ros2_control>
  <gazebo>
    <plugin filename="libgazebo_ros2_control.so" name="gazebo_ros2_control">
      <!--Gazebo 插件桥接-->
      <parameters>/home/bazi/patrol_robot/robot_ws/install/patrol_robot_description/share/patrol_robot_description/config/pabot_ros2_controller.yaml</parameters>
      <!--定义具体控制器-->
      <ros>
        <remapping>/pabot_diff_drive_controller/odom:=/odom</remapping>
        <!--让导航包使用标准 /odom-->
        <remapping>/pabot_diff_drive_controller/cmd_vel_unstamped:=/cmd_vel</remapping>
        <!--兼容 nav2 的速度控制命令-->
      </ros>
    </plugin>
  </gazebo>
</robot>
